```ts
export async function getCaptcha(api: captcha_api, data) {
    try {
        const captch_link = api.get_api_link();
        const response = await request.post(captch_link, data, {});
        return Promise.resolve(response);
    } catch (error: any) {
        return Promise.reject({
            message:
                error.message ||
                "Something went wrong, please contact for support",
        });
    }
}
```
你的问题涉及到如何判断一个 `Promise` 是 **resolved** 还是 **rejected**，以及 `async/await` 和 `try...catch` 的行为。

### **1. 基本行为：`Promise.resolve` vs `Promise.reject`**

在 `getCaptcha` 函数中：

- 如果 `request.post` 成功，`Promise.resolve(response)` 会返回一个被 **resolved** 的 Promise。
- 如果 `request.post` 抛出异常（`catch` 块被触发），`Promise.reject` 会返回一个被 **rejected** 的 Promise。

在调用这个函数的地方：

- **使用 `await` 的代码会抛出异常（如 `try...catch` 捕获）。**
- **不使用 `await` 时，可以通过 `.then` 和 `.catch` 来分别处理 `resolve` 和 `reject`。**

### **2. 如何判断是 `resolve` 还是 `reject`**

#### **场景 1：使用 `await` 和 `try...catch`**

```typescript
try {
    const response = await getCaptcha(api, data);
    console.log("Resolved:", response);
} catch (error) {
    console.error("Rejected:", error);
}
```

- 如果 `getCaptcha` 的 `Promise` 是 **resolved**，代码会进入 `try` 块。
- 如果是 **rejected**，代码会进入 `catch` 块。

#### **场景 2：使用 `.then` 和 `.catch`**

```typescript
getCaptcha(api, data)
    .then((response) => {
        console.log("Resolved:", response);
    })
    .catch((error) => {
        console.error("Rejected:", error);
    });
```

- `.then` 中的回调函数只会在 **resolve** 时调用。
- `.catch` 中的回调函数只会在 **reject** 时调用。

#### **场景 3：同时处理 `resolve` 和 `reject`**

```typescript
getCaptcha(api, data)
    .then(
        (response) => console.log("Resolved:", response),
        (error) => console.error("Rejected:", error) // 处理 reject
    );
```

这种方式的 `then` 有两个回调参数，第一个处理 **resolved** 的结果，第二个处理 **rejected** 的错误。

---

### **3. `await` 与 `try...catch` 的特性**

- **带 `await` 的 Promise**：如果 Promise 是 rejected，`await` 会抛出一个异常，这个异常需要用 `try...catch` 捕获。
- **不带 `await` 的 Promise**：调用时直接返回一个 Promise，需要用 `.then` 或 `.catch` 处理。

例如：

```typescript
async function test() {
    const promise = getCaptcha(api, data); // 返回一个 Promise
    console.log("Promise created:", promise);

    try {
        const response = await promise;
        console.log("Resolved:", response);
    } catch (error) {
        console.error("Rejected:", error);
    }
}
```

---

### **4. 如何确认 Promise 是否 Resolved 或 Rejected**

如果你需要在代码中判断某个 Promise 的状态（`resolved` 或 `rejected`），可以使用 `.then` 和 `.catch` 的组合来明确处理。例如：

```typescript
function isResolvedOrRejected(promise) {
    return promise
        .then(
            (value) => ({ status: "resolved", value }),
            (error) => ({ status: "rejected", error })
        );
}

const promise = getCaptcha(api, data);

isResolvedOrRejected(promise).then((result) => {
    if (result.status === "resolved") {
        console.log("Promise resolved with value:", result.value);
    } else {
        console.error("Promise rejected with error:", result.error);
    }
});
```

---

### **总结**

- **带 `await` 的 Promise** 会通过 `try...catch` 判断是 **resolved** 还是 **rejected**。
- **不带 `await` 的 Promise** 可以用 `.then` 和 `.catch` 显式处理状态。
- 如果需要检查状态，可以通过包装一个函数返回状态和数据的结构体（如 `{status, value/error}`）来实现。