是的，使用 `Promise.resolve` 和 `Promise.reject` 是一种简洁的方法，能够将结果和错误进行统一封装，从而更方便地在外部调用时处理逻辑。

对于带有 axios 请求的函数部分, 一般都需要采用  async 和 await 进行异步请求编写和 try... catch 返回逻辑, 因为只要状态码不是 2xx 就返回错误, 必须进行 try  ... catch 

```ts
export async function loginUserByUsername(login_form_data: any): Promise<any> {
    try {
        const response = await request.post("auth/login/name", login_form_data);
        return Promise.resolve(response);
    } catch (error: any) {
        if (axios.isAxiosError(error)) {
            const errorMsg =
                error.response?.data?.error?.message ||
                "Unknown error";
            const statusCode = error.status;
            return Promise.reject({
                error: errorMsg,
                error_code: statusCode,
            });
        } else {
            return Promise.reject({
                error: error.message || "Unknown error",
                error_code: 500,
            });
        }
    }
}
```

具体 errMsg 从哪里取得, 需要根据实际后端响应进行判断, 并用 `error.response.data` 访问，例如以上返回格式是: 
```json 
{
	"succeed":False, 
	"error":{
		"message" : "request failed",
	}
}
```
而状态码可以直接从  status.error  获取。


### 在外部处理返回结果

外部调用 `loginUserByUsername` 时，可以使用 `then` 和 `catch` 处理成功和失败的结果。

#### 示例代码

```typescript
if (data_res.valid === true) {
    const form_data = JSON.stringify(this.LoginForm_username);

    loginUserByUsername(form_data)
        .then(response => {
            // 成功的响应
            if (response.status === 200) {
                alert("Login Success");
            }
        })
        .catch(error => {
            // 失败的响应
            alert(`Login failed: ${error.message}`);
            console.error("Error details:", error);
        });
}
```

---

### 优点

1. **统一返回结构**：
    
    - 成功时通过 `Promise.resolve` 返回标准响应。
    - 失败时通过 `Promise.reject` 返回标准错误对象。
2. **简化调用代码**：
    
    - 外部调用时直接使用 `then` 和 `catch` 处理逻辑，无需再写额外的 `try-catch` 块。
3. **支持链式调用**：
    
    - 允许在链式调用中对结果进行进一步处理。

---

### 改进点：使用 `async/await` 处理返回结果

为了让代码更加现代化和易读，可以在外部用 `async/await` 的方式处理返回结果，并通过 `try-catch` 捕获错误。

#### 示例代码

```typescript
if (data_res.valid === true) {
    try {
        const form_data = JSON.stringify(this.LoginForm_username);

        // 使用 await 调用 loginUserByUsername
        const response = await loginUserByUsername(form_data);

        if (response.status === 200) {
            alert("Login Success");
        }
    } catch (error) {
        // 捕获 Promise.reject 的错误
        alert(`Login failed: ${error.message}`);
        console.error("Error details:", error);
    }
}
```

---

### 总结

- **使用 `Promise.resolve` 和 `Promise.reject`** 提供了一种更清晰的方式来管理成功和失败的返回值。
- 外部代码可以灵活地选择使用 `then/catch` 或 `async/await` 处理结果。
- 在 `catch` 块中，可以直接访问错误对象中的 `status` 和 `message`，从而轻松反馈给用户并记录日志。